2025-05-20 17:48:54,615 - INFO - sendTrujillo.py:94 - Sistema de Logging configurado.
2025-05-20 17:48:54,616 - INFO - sendTrujillo.py:149 - ********** INICIO DEL PROCESO DE ENVÍO DE INFORMES **********
2025-05-20 17:48:56,742 - INFO - sendTrujillo.py:169 - Se encontraron 1 CDAMOSTRAS pendientes para procesar.
2025-05-20 17:48:56,743 - INFO - sendTrujillo.py:102 - --- Iniciando procesamiento para CDAMOSTRA: 3231808 ---
2025-05-20 17:48:57,351 - INFO - sendTrujillo.py:114 - Resultados obtenidos para 3231808: 2 filas.
2025-05-20 17:48:57,822 - INFO - sendTrujillo.py:126 - Encabezado obtenido para 3231808.
2025-05-20 17:49:49,940 - ERROR - sendTrujillo.py:238 - No se pudo generar el archivo Excel para CDAMOSTRA 3231808. No se enviará correo.
2025-05-20 17:49:49,944 - INFO - sendTrujillo.py:241 - --- Proceso completado para todos los pendientes ---
2025-05-20 17:49:50,099 - INFO - sendTrujillo.py:252 - ********** FIN DEL PROCESO DE ENVÍO DE INFORMES **********
2025-05-20 17:54:04,175 - INFO - sendTrujillo.py:94 - Sistema de Logging configurado.
2025-05-20 17:54:04,176 - INFO - sendTrujillo.py:149 - ********** INICIO DEL PROCESO DE ENVÍO DE INFORMES **********
2025-05-20 17:54:06,274 - INFO - sendTrujillo.py:169 - Se encontraron 1 CDAMOSTRAS pendientes para procesar.
2025-05-20 17:54:06,274 - INFO - sendTrujillo.py:102 - --- Iniciando procesamiento para CDAMOSTRA: 3231808 ---
2025-05-20 17:54:06,888 - INFO - sendTrujillo.py:114 - Resultados obtenidos para 3231808: 2 filas.
2025-05-20 17:54:07,344 - INFO - sendTrujillo.py:126 - Encabezado obtenido para 3231808.
2025-05-20 17:54:31,486 - INFO - generador_excel.py:109 - Directorio para Excel creado: informes_generados
2025-05-20 17:54:49,100 - INFO - sendTrujillo.py:209 - Excel 'informes_generados\Trujillo_Muestra_3231808.xlsx' generado exitosamente para CDAMOSTRA 3231808.
2025-05-20 17:55:46,501 - INFO - manejador_correo.py:150 - Archivo 'Trujillo_Muestra_3231808.xlsx' adjuntado al correo.
2025-05-20 17:55:54,150 - ERROR - manejador_correo.py:181 - Error al enviar el correo: [Errno 11001] getaddrinfo failed
Traceback (most recent call last):
  File "C:\xampp\htdocs\HORTISAFE\manejador_correo.py", line 163, in enviar_correo_con_adjunto
    server = smtplib.SMTP(SMTP_SERVER, SMTP_PORT)
  File "c:\Users\Usuario\AppData\Local\Programs\Python\Python313\Lib\smtplib.py", line 255, in __init__
    (code, msg) = self.connect(host, port)
                  ~~~~~~~~~~~~^^^^^^^^^^^^
  File "c:\Users\Usuario\AppData\Local\Programs\Python\Python313\Lib\smtplib.py", line 341, in connect
    self.sock = self._get_socket(host, port, self.timeout)
                ~~~~~~~~~~~~~~~~^^^^^^^^^^^^^^^^^^^^^^^^^^
  File "c:\Users\Usuario\AppData\Local\Programs\Python\Python313\Lib\smtplib.py", line 312, in _get_socket
    return socket.create_connection((host, port), timeout,
           ~~~~~~~~~~~~~~~~~~~~~~~~^^^^^^^^^^^^^^^^^^^^^^^
                                    self.source_address)
                                    ^^^^^^^^^^^^^^^^^^^^
  File "c:\Users\Usuario\AppData\Local\Programs\Python\Python313\Lib\socket.py", line 840, in create_connection
    for res in getaddrinfo(host, port, 0, SOCK_STREAM):
               ~~~~~~~~~~~^^^^^^^^^^^^^^^^^^^^^^^^^^^^
  File "c:\Users\Usuario\AppData\Local\Programs\Python\Python313\Lib\socket.py", line 977, in getaddrinfo
    for res in _socket.getaddrinfo(host, port, family, type, proto, flags):
               ~~~~~~~~~~~~~~~~~~~^^^^^^^^^^^^^^^^^^^^^^^^^^^^^^^^^^^^^^^^
socket.gaierror: [Errno 11001] getaddrinfo failed
2025-05-20 17:55:59,238 - ERROR - sendTrujillo.py:235 - Fallo al enviar correo para CDAMOSTRA 3231808 con adjunto 'Trujillo_Muestra_3231808.xlsx'.
2025-05-20 17:55:59,239 - INFO - sendTrujillo.py:241 - --- Proceso completado para todos los pendientes ---
2025-05-20 17:55:59,384 - INFO - sendTrujillo.py:252 - ********** FIN DEL PROCESO DE ENVÍO DE INFORMES **********
2025-05-20 18:05:12,413 - INFO - sendTrujillo.py:94 - Sistema de Logging configurado.
2025-05-20 18:05:12,417 - INFO - sendTrujillo.py:149 - ********** INICIO DEL PROCESO DE ENVÍO DE INFORMES **********
2025-05-20 18:05:14,572 - INFO - sendTrujillo.py:169 - Se encontraron 1 CDAMOSTRAS pendientes para procesar.
2025-05-20 18:05:14,573 - INFO - sendTrujillo.py:102 - --- Iniciando procesamiento para CDAMOSTRA: 3231808 ---
2025-05-20 18:05:15,189 - INFO - sendTrujillo.py:114 - Resultados obtenidos para 3231808: 2 filas.
2025-05-20 18:05:16,268 - INFO - sendTrujillo.py:126 - Encabezado obtenido para 3231808.
2025-05-20 18:05:17,587 - INFO - sendTrujillo.py:209 - Excel 'informes_generados\Trujillo_Muestra_3231808.xlsx' generado exitosamente para CDAMOSTRA 3231808.
2025-05-20 18:05:47,906 - INFO - manejador_correo.py:150 - Archivo 'Trujillo_Muestra_3231808.xlsx' adjuntado al correo.
2025-05-20 18:06:04,761 - ERROR - manejador_correo.py:178 - Error de autenticación SMTP: (535, b'5.7.139 Authentication unsuccessful, SmtpClientAuthentication is disabled for the Tenant. Visit https://aka.ms/smtp_auth_disabled for more information. [CP4P284CA0018.BRAP284.PROD.OUTLOOK.COM 2025-05-20T23:06:04.791Z 08DD96F07C0B924C]'). Verifica usuario/contraseña.
Traceback (most recent call last):
  File "C:\xampp\htdocs\HORTISAFE\manejador_correo.py", line 172, in enviar_correo_con_adjunto
    server.login(SMTP_USER, SMTP_PASSWORD)
    ~~~~~~~~~~~~^^^^^^^^^^^^^^^^^^^^^^^^^^
  File "c:\Users\Usuario\AppData\Local\Programs\Python\Python313\Lib\smtplib.py", line 750, in login
    raise last_exception
  File "c:\Users\Usuario\AppData\Local\Programs\Python\Python313\Lib\smtplib.py", line 739, in login
    (code, resp) = self.auth(
                   ~~~~~~~~~^
        authmethod, getattr(self, method_name),
        ^^^^^^^^^^^^^^^^^^^^^^^^^^^^^^^^^^^^^^^
        initial_response_ok=initial_response_ok)
        ^^^^^^^^^^^^^^^^^^^^^^^^^^^^^^^^^^^^^^^^
  File "c:\Users\Usuario\AppData\Local\Programs\Python\Python313\Lib\smtplib.py", line 662, in auth
    raise SMTPAuthenticationError(code, resp)
smtplib.SMTPAuthenticationError: (535, b'5.7.139 Authentication unsuccessful, SmtpClientAuthentication is disabled for the Tenant. Visit https://aka.ms/smtp_auth_disabled for more information. [CP4P284CA0018.BRAP284.PROD.OUTLOOK.COM 2025-05-20T23:06:04.791Z 08DD96F07C0B924C]')
2025-05-20 18:06:09,633 - ERROR - sendTrujillo.py:235 - Fallo al enviar correo para CDAMOSTRA 3231808 con adjunto 'Trujillo_Muestra_3231808.xlsx'.
2025-05-20 18:06:11,103 - INFO - sendTrujillo.py:241 - --- Proceso completado para todos los pendientes ---
2025-05-20 18:06:11,266 - INFO - sendTrujillo.py:252 - ********** FIN DEL PROCESO DE ENVÍO DE INFORMES **********
2025-05-20 18:08:15,454 - INFO - sendTrujillo.py:94 - Sistema de Logging configurado.
2025-05-20 18:08:15,456 - INFO - sendTrujillo.py:149 - ********** INICIO DEL PROCESO DE ENVÍO DE INFORMES **********
2025-05-20 18:08:17,569 - INFO - sendTrujillo.py:169 - Se encontraron 1 CDAMOSTRAS pendientes para procesar.
2025-05-20 18:08:17,576 - INFO - sendTrujillo.py:102 - --- Iniciando procesamiento para CDAMOSTRA: 3231808 ---
2025-05-20 18:08:18,233 - INFO - sendTrujillo.py:114 - Resultados obtenidos para 3231808: 2 filas.
2025-05-20 18:08:18,744 - INFO - sendTrujillo.py:126 - Encabezado obtenido para 3231808.
2025-05-20 18:08:23,853 - INFO - sendTrujillo.py:209 - Excel 'informes_generados\Trujillo_Muestra_3231808.xlsx' generado exitosamente para CDAMOSTRA 3231808.
2025-05-20 18:08:23,913 - INFO - manejador_correo.py:150 - Archivo 'Trujillo_Muestra_3231808.xlsx' adjuntado al correo.
2025-05-20 18:09:08,506 - ERROR - manejador_correo.py:178 - Error de autenticación SMTP: (535, b'5.7.139 Authentication unsuccessful, SmtpClientAuthentication is disabled for the Tenant. Visit https://aka.ms/smtp_auth_disabled for more information. [CPYP284CA0031.BRAP284.PROD.OUTLOOK.COM 2025-05-20T23:09:04.435Z 08DD96D706320880]'). Verifica usuario/contraseña.
Traceback (most recent call last):
  File "C:\xampp\htdocs\HORTISAFE\manejador_correo.py", line 172, in enviar_correo_con_adjunto
    server.login(SMTP_USER, SMTP_PASSWORD)
    ~~~~~~~~~~~~^^^^^^^^^^^^^^^^^^^^^^^^^^
  File "c:\Users\Usuario\AppData\Local\Programs\Python\Python313\Lib\smtplib.py", line 750, in login
    raise last_exception
  File "c:\Users\Usuario\AppData\Local\Programs\Python\Python313\Lib\smtplib.py", line 739, in login
    (code, resp) = self.auth(
                   ~~~~~~~~~^
        authmethod, getattr(self, method_name),
        ^^^^^^^^^^^^^^^^^^^^^^^^^^^^^^^^^^^^^^^
        initial_response_ok=initial_response_ok)
        ^^^^^^^^^^^^^^^^^^^^^^^^^^^^^^^^^^^^^^^^
  File "c:\Users\Usuario\AppData\Local\Programs\Python\Python313\Lib\smtplib.py", line 662, in auth
    raise SMTPAuthenticationError(code, resp)
smtplib.SMTPAuthenticationError: (535, b'5.7.139 Authentication unsuccessful, SmtpClientAuthentication is disabled for the Tenant. Visit https://aka.ms/smtp_auth_disabled for more information. [CPYP284CA0031.BRAP284.PROD.OUTLOOK.COM 2025-05-20T23:09:04.435Z 08DD96D706320880]')
2025-05-20 18:09:08,522 - ERROR - sendTrujillo.py:235 - Fallo al enviar correo para CDAMOSTRA 3231808 con adjunto 'Trujillo_Muestra_3231808.xlsx'.
2025-05-20 18:09:08,523 - INFO - sendTrujillo.py:241 - --- Proceso completado para todos los pendientes ---
2025-05-20 18:09:08,685 - INFO - sendTrujillo.py:252 - ********** FIN DEL PROCESO DE ENVÍO DE INFORMES **********
2025-05-20 18:16:07,587 - INFO - sendTrujillo.py:94 - Sistema de Logging configurado.
2025-05-20 18:16:07,588 - INFO - sendTrujillo.py:149 - ********** INICIO DEL PROCESO DE ENVÍO DE INFORMES **********
2025-05-20 18:16:09,681 - INFO - sendTrujillo.py:169 - Se encontraron 1 CDAMOSTRAS pendientes para procesar.
2025-05-20 18:16:09,681 - INFO - sendTrujillo.py:102 - --- Iniciando procesamiento para CDAMOSTRA: 3231808 ---
2025-05-20 18:16:10,300 - INFO - sendTrujillo.py:114 - Resultados obtenidos para 3231808: 2 filas.
2025-05-20 18:16:10,755 - INFO - sendTrujillo.py:126 - Encabezado obtenido para 3231808.
2025-05-20 18:16:11,767 - INFO - sendTrujillo.py:209 - Excel 'informes_generados\Trujillo_Muestra_3231808.xlsx' generado exitosamente para CDAMOSTRA 3231808.
2025-05-20 18:16:11,866 - INFO - manejador_correo.py:150 - Archivo 'Trujillo_Muestra_3231808.xlsx' adjuntado al correo.
2025-05-20 18:16:28,424 - ERROR - manejador_correo.py:178 - Error de autenticación SMTP: (535, b'5.7.139 Authentication unsuccessful, the user credentials were incorrect. [CP5P284CA0186.BRAP284.PROD.OUTLOOK.COM 2025-05-20T23:16:28.198Z 08DD977080908BCF]'). Verifica usuario/contraseña.
Traceback (most recent call last):
  File "C:\xampp\htdocs\HORTISAFE\manejador_correo.py", line 172, in enviar_correo_con_adjunto
    server.login(SMTP_USER, SMTP_PASSWORD)
    ~~~~~~~~~~~~^^^^^^^^^^^^^^^^^^^^^^^^^^
  File "c:\Users\Usuario\AppData\Local\Programs\Python\Python313\Lib\smtplib.py", line 750, in login
    raise last_exception
  File "c:\Users\Usuario\AppData\Local\Programs\Python\Python313\Lib\smtplib.py", line 739, in login
    (code, resp) = self.auth(
                   ~~~~~~~~~^
        authmethod, getattr(self, method_name),
        ^^^^^^^^^^^^^^^^^^^^^^^^^^^^^^^^^^^^^^^
        initial_response_ok=initial_response_ok)
        ^^^^^^^^^^^^^^^^^^^^^^^^^^^^^^^^^^^^^^^^
  File "c:\Users\Usuario\AppData\Local\Programs\Python\Python313\Lib\smtplib.py", line 662, in auth
    raise SMTPAuthenticationError(code, resp)
smtplib.SMTPAuthenticationError: (535, b'5.7.139 Authentication unsuccessful, the user credentials were incorrect. [CP5P284CA0186.BRAP284.PROD.OUTLOOK.COM 2025-05-20T23:16:28.198Z 08DD977080908BCF]')
2025-05-20 18:20:06,501 - INFO - sendTrujillo.py:94 - Sistema de Logging configurado.
2025-05-20 18:20:06,503 - INFO - sendTrujillo.py:149 - ********** INICIO DEL PROCESO DE ENVÍO DE INFORMES **********
2025-05-20 18:20:08,555 - INFO - sendTrujillo.py:169 - Se encontraron 1 CDAMOSTRAS pendientes para procesar.
2025-05-20 18:20:08,556 - INFO - sendTrujillo.py:102 - --- Iniciando procesamiento para CDAMOSTRA: 3231808 ---
2025-05-20 18:20:09,226 - INFO - sendTrujillo.py:114 - Resultados obtenidos para 3231808: 2 filas.
2025-05-20 18:20:09,692 - INFO - sendTrujillo.py:126 - Encabezado obtenido para 3231808.
2025-05-20 18:20:10,415 - INFO - sendTrujillo.py:209 - Excel 'informes_generados\Trujillo_Muestra_3231808.xlsx' generado exitosamente para CDAMOSTRA 3231808.
2025-05-20 18:20:10,534 - INFO - manejador_correo.py:169 - Archivo 'Trujillo_Muestra_3231808.xlsx' adjuntado al correo.
2025-05-20 18:20:27,914 - INFO - manejador_correo.py:193 - Intentando login SMTP a smtp.office365.com:587 con usuario noreply.new@ceimic.com
2025-05-20 18:20:36,255 - ERROR - manejador_correo.py:202 - Error de autenticación SMTP: (535, b'5.7.139 Authentication unsuccessful, the user credentials were incorrect. [CP6P284CA0064.BRAP284.PROD.OUTLOOK.COM 2025-05-20T23:20:37.968Z 08DD97549355C14C]'). Verifica usuario/contraseña y configuración del servidor.
Traceback (most recent call last):
  File "C:\xampp\htdocs\HORTISAFE\manejador_correo.py", line 194, in enviar_correo_con_adjunto
    server.login(SMTP_USER, SMTP_PASSWORD)
    ~~~~~~~~~~~~^^^^^^^^^^^^^^^^^^^^^^^^^^
  File "c:\Users\Usuario\AppData\Local\Programs\Python\Python313\Lib\smtplib.py", line 750, in login
    raise last_exception
  File "c:\Users\Usuario\AppData\Local\Programs\Python\Python313\Lib\smtplib.py", line 739, in login
    (code, resp) = self.auth(
                   ~~~~~~~~~^
        authmethod, getattr(self, method_name),
        ^^^^^^^^^^^^^^^^^^^^^^^^^^^^^^^^^^^^^^^
        initial_response_ok=initial_response_ok)
        ^^^^^^^^^^^^^^^^^^^^^^^^^^^^^^^^^^^^^^^^
  File "c:\Users\Usuario\AppData\Local\Programs\Python\Python313\Lib\smtplib.py", line 662, in auth
    raise SMTPAuthenticationError(code, resp)
smtplib.SMTPAuthenticationError: (535, b'5.7.139 Authentication unsuccessful, the user credentials were incorrect. [CP6P284CA0064.BRAP284.PROD.OUTLOOK.COM 2025-05-20T23:20:37.968Z 08DD97549355C14C]')
2025-05-20 18:20:40,769 - ERROR - sendTrujillo.py:235 - Fallo al enviar correo para CDAMOSTRA 3231808 con adjunto 'Trujillo_Muestra_3231808.xlsx'.
2025-05-20 18:20:40,770 - INFO - sendTrujillo.py:241 - --- Proceso completado para todos los pendientes ---
2025-05-20 18:20:40,922 - INFO - sendTrujillo.py:252 - ********** FIN DEL PROCESO DE ENVÍO DE INFORMES **********
2025-05-20 18:23:43,005 - INFO - sendTrujillo.py:94 - Sistema de Logging configurado.
2025-05-20 18:23:43,007 - INFO - sendTrujillo.py:149 - ********** INICIO DEL PROCESO DE ENVÍO DE INFORMES **********
2025-05-20 18:23:45,052 - INFO - sendTrujillo.py:169 - Se encontraron 1 CDAMOSTRAS pendientes para procesar.
2025-05-20 18:23:45,053 - INFO - sendTrujillo.py:102 - --- Iniciando procesamiento para CDAMOSTRA: 3231808 ---
2025-05-20 18:23:45,817 - INFO - sendTrujillo.py:114 - Resultados obtenidos para 3231808: 2 filas.
2025-05-20 18:23:46,282 - INFO - sendTrujillo.py:126 - Encabezado obtenido para 3231808.
2025-05-20 18:23:46,945 - INFO - generador_excel.py:112 -  Excel para Trujillo 'informes_generados\Trujillo_Muestra_3231808.xlsx' creado exitosamente para muestra PACK 2 SUPER EXPRESS.
2025-05-20 18:23:46,946 - INFO - sendTrujillo.py:209 - Excel 'informes_generados\Trujillo_Muestra_3231808.xlsx' generado exitosamente para CDAMOSTRA 3231808.
2025-05-20 18:23:46,973 - INFO - manejador_correo.py:169 - Archivo 'Trujillo_Muestra_3231808.xlsx' adjuntado al correo.
2025-05-20 18:23:52,240 - INFO - manejador_correo.py:193 - Intentando login SMTP a smtp.office365.com:587 con usuario noreply.new@ceimic.com
2025-05-20 18:23:59,796 - ERROR - manejador_correo.py:202 - Error de autenticación SMTP: (535, b'5.7.139 Authentication unsuccessful, the user credentials were incorrect. [CP5P284CA0142.BRAP284.PROD.OUTLOOK.COM 2025-05-20T23:24:01.691Z 08DD979E5564C2A4]'). Verifica usuario/contraseña y configuración del servidor.
Traceback (most recent call last):
  File "C:\xampp\htdocs\HORTISAFE\manejador_correo.py", line 194, in enviar_correo_con_adjunto
    server.login(SMTP_USER, SMTP_PASSWORD)
    ~~~~~~~~~~~~^^^^^^^^^^^^^^^^^^^^^^^^^^
  File "c:\Users\Usuario\AppData\Local\Programs\Python\Python313\Lib\smtplib.py", line 750, in login
    raise last_exception
  File "c:\Users\Usuario\AppData\Local\Programs\Python\Python313\Lib\smtplib.py", line 739, in login
    (code, resp) = self.auth(
                   ~~~~~~~~~^
        authmethod, getattr(self, method_name),
        ^^^^^^^^^^^^^^^^^^^^^^^^^^^^^^^^^^^^^^^
        initial_response_ok=initial_response_ok)
        ^^^^^^^^^^^^^^^^^^^^^^^^^^^^^^^^^^^^^^^^
  File "c:\Users\Usuario\AppData\Local\Programs\Python\Python313\Lib\smtplib.py", line 662, in auth
    raise SMTPAuthenticationError(code, resp)
smtplib.SMTPAuthenticationError: (535, b'5.7.139 Authentication unsuccessful, the user credentials were incorrect. [CP5P284CA0142.BRAP284.PROD.OUTLOOK.COM 2025-05-20T23:24:01.691Z 08DD979E5564C2A4]')
2025-05-20 18:24:02,470 - ERROR - sendTrujillo.py:235 - Fallo al enviar correo para CDAMOSTRA 3231808 con adjunto 'Trujillo_Muestra_3231808.xlsx'.
2025-05-20 18:24:02,471 - INFO - sendTrujillo.py:241 - --- Proceso completado para todos los pendientes ---
2025-05-20 18:24:02,623 - INFO - sendTrujillo.py:252 - ********** FIN DEL PROCESO DE ENVÍO DE INFORMES **********
2025-05-20 20:59:24,403 - INFO - sendTrujillo.py:95 - Sistema de Logging configurado.
2025-05-20 20:59:24,404 - INFO - sendTrujillo.py:150 - ********** INICIO DEL PROCESO DE ENVÍO DE INFORMES **********
2025-05-20 20:59:26,671 - INFO - sendTrujillo.py:170 - Se encontraron 1 CDAMOSTRAS pendientes para procesar.
2025-05-20 20:59:26,671 - INFO - sendTrujillo.py:103 - --- Iniciando procesamiento para CDAMOSTRA: 3231808 ---
2025-05-20 20:59:27,489 - INFO - sendTrujillo.py:115 - Resultados obtenidos para 3231808: 2 filas.
2025-05-20 20:59:28,058 - INFO - sendTrujillo.py:127 - Encabezado obtenido para 3231808.
2025-05-20 20:59:29,226 - INFO - generador_excel.py:113 -  Excel para Trujillo 'informes_generados\Trujillo_Muestra_3231808.xlsx' creado exitosamente para muestra PACK 2 SUPER EXPRESS.
2025-05-20 20:59:29,228 - INFO - sendTrujillo.py:210 - Excel 'informes_generados\Trujillo_Muestra_3231808.xlsx' generado exitosamente para CDAMOSTRA 3231808.
2025-05-20 20:59:29,256 - INFO - manejador_correo.py:170 - Archivo 'Trujillo_Muestra_3231808.xlsx' adjuntado al correo.
2025-05-20 20:59:47,364 - INFO - manejador_correo.py:194 - Intentando login SMTP a smtp.office365.com:587 con usuario resultados@ceimic.com
2025-05-20 20:59:57,362 - ERROR - manejador_correo.py:203 - Error de autenticación SMTP: (535, b'5.7.139 Authentication unsuccessful, the user credentials were incorrect. [CP5P284CA0266.BRAP284.PROD.OUTLOOK.COM 2025-05-21T01:59:58.683Z 08DD97724B700F22]'). Verifica usuario/contraseña y configuración del servidor.
Traceback (most recent call last):
  File "C:\xampp\htdocs\HORTISAFE\manejador_correo.py", line 195, in enviar_correo_con_adjunto
    server.login(SMTP_USER, SMTP_PASSWORD)
    ~~~~~~~~~~~~^^^^^^^^^^^^^^^^^^^^^^^^^^
  File "c:\Users\Usuario\AppData\Local\Programs\Python\Python313\Lib\smtplib.py", line 750, in login
    raise last_exception
  File "c:\Users\Usuario\AppData\Local\Programs\Python\Python313\Lib\smtplib.py", line 739, in login
    (code, resp) = self.auth(
                   ~~~~~~~~~^
        authmethod, getattr(self, method_name),
        ^^^^^^^^^^^^^^^^^^^^^^^^^^^^^^^^^^^^^^^
        initial_response_ok=initial_response_ok)
        ^^^^^^^^^^^^^^^^^^^^^^^^^^^^^^^^^^^^^^^^
  File "c:\Users\Usuario\AppData\Local\Programs\Python\Python313\Lib\smtplib.py", line 662, in auth
    raise SMTPAuthenticationError(code, resp)
smtplib.SMTPAuthenticationError: (535, b'5.7.139 Authentication unsuccessful, the user credentials were incorrect. [CP5P284CA0266.BRAP284.PROD.OUTLOOK.COM 2025-05-21T01:59:58.683Z 08DD97724B700F22]')
2025-05-20 21:00:02,949 - ERROR - sendTrujillo.py:236 - Fallo al enviar correo para CDAMOSTRA 3231808 con adjunto 'Trujillo_Muestra_3231808.xlsx'.
2025-05-20 21:00:02,949 - INFO - sendTrujillo.py:242 - --- Proceso completado para todos los pendientes ---
2025-05-20 21:00:03,125 - INFO - sendTrujillo.py:253 - ********** FIN DEL PROCESO DE ENVÍO DE INFORMES **********
2025-05-20 21:10:43,189 - INFO - sendTrujillo.py:97 - Sistema de Logging configurado.
2025-05-20 21:10:43,192 - INFO - sendTrujillo.py:152 - ********** INICIO DEL PROCESO DE ENVÍO DE INFORMES **********
2025-05-20 21:10:45,432 - INFO - sendTrujillo.py:172 - Se encontraron 1 CDAMOSTRAS pendientes para procesar.
2025-05-20 21:10:45,433 - INFO - sendTrujillo.py:105 - --- Iniciando procesamiento para CDAMOSTRA: 3231808 ---
2025-05-20 21:10:46,140 - INFO - sendTrujillo.py:117 - Resultados obtenidos para 3231808: 2 filas.
2025-05-20 21:10:46,607 - INFO - sendTrujillo.py:129 - Encabezado obtenido para 3231808.
2025-05-20 21:10:47,689 - INFO - generador_excel.py:113 -  Excel para Trujillo 'informes_generados\Trujillo_Muestra_3231808.xlsx' creado exitosamente para muestra PACK 2 SUPER EXPRESS.
2025-05-20 21:10:47,690 - INFO - sendTrujillo.py:212 - Excel 'informes_generados\Trujillo_Muestra_3231808.xlsx' generado exitosamente para CDAMOSTRA 3231808.
2025-05-20 21:10:47,693 - INFO - manejador_correo.py:121 - Archivo 'Trujillo_Muestra_3231808.xlsx' preparado para adjuntar.
2025-05-20 21:10:54,899 - INFO - manejador_correo.py:131 - Inicializando Yagmail para resultados@ceimic.com en smtp.office365.com:587
2025-05-20 21:11:02,743 - INFO - manejador_correo.py:148 - Intentando enviar correo a: ['usuario.final@cliente.com', 'otro.usuario@cliente.com'], Cc: ['supervisor@ceimic.com'], Bcc: ['auditoria.interna@ceimic.com']
2025-05-20 21:18:15,286 - INFO - sendTrujillo.py:98 - Sistema de Logging configurado.
2025-05-20 21:18:15,289 - INFO - sendTrujillo.py:153 - ********** INICIO DEL PROCESO DE ENVÍO DE INFORMES **********
2025-05-20 21:18:17,417 - INFO - sendTrujillo.py:173 - Se encontraron 1 CDAMOSTRAS pendientes para procesar.
2025-05-20 21:18:17,417 - INFO - sendTrujillo.py:106 - --- Iniciando procesamiento para CDAMOSTRA: 3231808 ---
2025-05-20 21:18:18,087 - INFO - sendTrujillo.py:118 - Resultados obtenidos para 3231808: 2 filas.
2025-05-20 21:18:18,598 - INFO - sendTrujillo.py:130 - Encabezado obtenido para 3231808.
2025-05-20 21:18:19,094 - INFO - generador_excel.py:113 -  Excel para Trujillo 'informes_generados\Trujillo_Muestra_3231808.xlsx' creado exitosamente para muestra PACK 2 SUPER EXPRESS.
2025-05-20 21:18:19,095 - INFO - sendTrujillo.py:213 - Excel 'informes_generados\Trujillo_Muestra_3231808.xlsx' generado exitosamente para CDAMOSTRA 3231808.
2025-05-20 21:18:19,096 - INFO - manejador_correo.py:108 - Archivo 'Trujillo_Muestra_3231808.xlsx' preparado para adjuntar.
2025-05-20 21:18:21,060 - INFO - manejador_correo.py:113 - Inicializando Yagmail para resultados@ceimic.com en smtp.office365.com:587
2025-05-20 21:18:25,860 - INFO - manejador_correo.py:132 - Intentando enviar correo a: ['usuario.final@cliente.com', 'otro.usuario@cliente.com'], Cc: ['supervisor@ceimic.com'], Bcc: ['auditoria.interna@ceimic.com']
2025-05-20 21:21:48,415 - INFO - sendTrujillo.py:98 - Sistema de Logging configurado.
2025-05-20 21:21:48,417 - INFO - sendTrujillo.py:153 - ********** INICIO DEL PROCESO DE ENVÍO DE INFORMES **********
2025-05-20 21:21:50,518 - INFO - sendTrujillo.py:173 - Se encontraron 1 CDAMOSTRAS pendientes para procesar.
2025-05-20 21:21:50,519 - INFO - sendTrujillo.py:106 - --- Iniciando procesamiento para CDAMOSTRA: 3231808 ---
2025-05-20 21:21:51,195 - INFO - sendTrujillo.py:118 - Resultados obtenidos para 3231808: 2 filas.
2025-05-20 21:21:51,699 - INFO - sendTrujillo.py:130 - Encabezado obtenido para 3231808.
2025-05-20 21:21:52,438 - INFO - generador_excel.py:113 -  Excel para Trujillo 'informes_generados\Trujillo_Muestra_3231808.xlsx' creado exitosamente para muestra PACK 2 SUPER EXPRESS.
2025-05-20 21:21:52,471 - INFO - sendTrujillo.py:213 - Excel 'informes_generados\Trujillo_Muestra_3231808.xlsx' generado exitosamente para CDAMOSTRA 3231808.
2025-05-20 21:21:52,476 - INFO - manejador_correo.py:109 - Archivo 'Trujillo_Muestra_3231808.xlsx' preparado para adjuntar.
2025-05-20 21:21:53,894 - INFO - manejador_correo.py:115 - Inicializando Yagmail para resultados@ceimic.com en smtp.office365.com:587
2025-05-20 21:21:57,725 - INFO - manejador_correo.py:133 - Intentando enviar correo a: ['usuario.final@cliente.com', 'otro.usuario@cliente.com'], Cc: ['supervisor@ceimic.com'], Bcc: ['auditoria.interna@ceimic.com']
2025-05-20 21:22:10,312 - ERROR - manejador_correo.py:148 - Error de AUTENTICACIÓN SMTP (desde yagmail/smtplib): (535, b'5.7.139 Authentication unsuccessful, the user credentials were incorrect. [CP5P284CA0142.BRAP284.PROD.OUTLOOK.COM 2025-05-21T02:22:11.801Z 08DD979E55658BD5]')
2025-05-20 21:22:11,097 - ERROR - manejador_correo.py:149 - CAUSA MÁS PROBABLE: Credenciales incorrectas o la cuenta requiere una 'Contraseña de Aplicación' debido a MFA en Office 365.
2025-05-20 21:22:17,521 - ERROR - sendTrujillo.py:239 - Fallo al enviar correo para CDAMOSTRA 3231808 con adjunto 'Trujillo_Muestra_3231808.xlsx'.
2025-05-20 21:22:17,523 - INFO - sendTrujillo.py:245 - --- Proceso completado para todos los pendientes ---
2025-05-20 21:22:17,714 - INFO - sendTrujillo.py:256 - ********** FIN DEL PROCESO DE ENVÍO DE INFORMES **********
2025-05-21 08:21:42,475 - INFO - sendTrujillo.py:98 - Sistema de Logging configurado.
2025-05-21 08:21:42,476 - INFO - sendTrujillo.py:153 - ********** INICIO DEL PROCESO DE ENVÍO DE INFORMES **********
2025-05-21 08:21:44,664 - INFO - sendTrujillo.py:173 - Se encontraron 1 CDAMOSTRAS pendientes para procesar.
2025-05-21 08:21:44,665 - INFO - sendTrujillo.py:106 - --- Iniciando procesamiento para CDAMOSTRA: 3231808 ---
2025-05-21 08:21:45,791 - INFO - sendTrujillo.py:118 - Resultados obtenidos para 3231808: 2 filas.
2025-05-21 08:21:46,364 - INFO - sendTrujillo.py:130 - Encabezado obtenido para 3231808.
2025-05-21 08:21:47,329 - INFO - generador_excel.py:113 -  Excel para Trujillo 'informes_generados\Trujillo_Muestra_3231808.xlsx' creado exitosamente para muestra PACK 2 SUPER EXPRESS.
2025-05-21 08:21:47,330 - INFO - sendTrujillo.py:213 - Excel 'informes_generados\Trujillo_Muestra_3231808.xlsx' generado exitosamente para CDAMOSTRA 3231808.
2025-05-21 08:21:47,332 - INFO - manejador_correo.py:109 - Archivo 'Trujillo_Muestra_3231808.xlsx' preparado para adjuntar.
2025-05-21 08:21:49,464 - INFO - manejador_correo.py:115 - Inicializando Yagmail para noreply.new@ceimic.com en smtp.office365.com:587
2025-05-21 08:21:54,929 - INFO - manejador_correo.py:133 - Intentando enviar correo a: ['usuario.final@cliente.com', 'otro.usuario@cliente.com'], Cc: ['supervisor@ceimic.com'], Bcc: ['auditoria.interna@ceimic.com']
2025-05-21 08:22:03,506 - ERROR - errorhandler.py:105 - Selector: Unexpected CHAR. [1:1: <]
2025-05-21 08:22:03,511 - ERROR - errorhandler.py:105 - SelectorList: Invalid Selector: <br>            body 
2025-05-21 08:22:03,611 - ERROR - errorhandler.py:105 - Selector: Unexpected CHAR. [1:75: <]
2025-05-21 08:22:03,613 - ERROR - errorhandler.py:105 - SelectorList: Invalid Selector: <br>            .container 
2025-05-21 08:22:04,178 - ERROR - errorhandler.py:105 - Selector: Unexpected CHAR. [1:178: <]
2025-05-21 08:22:04,178 - ERROR - errorhandler.py:105 - SelectorList: Invalid Selector: <br>            .header 
2025-05-21 08:22:04,260 - ERROR - errorhandler.py:105 - Selector: Unexpected CHAR. [1:267: <]
2025-05-21 08:22:04,261 - ERROR - errorhandler.py:105 - SelectorList: Invalid Selector: <br>            .content p 
2025-05-21 08:22:04,268 - ERROR - errorhandler.py:105 - Selector: Unexpected CHAR. [1:318: <]
2025-05-21 08:22:04,269 - ERROR - errorhandler.py:105 - SelectorList: Invalid Selector: <br>            .footer 
2025-05-21 08:22:04,354 - ERROR - errorhandler.py:105 - Selector: Unexpected CHAR. [1:394: <]
2025-05-21 08:22:04,355 - ERROR - errorhandler.py:105 - SelectorList: Invalid Selector: <br>            table 
2025-05-21 08:22:04,364 - ERROR - errorhandler.py:105 - Selector: Unexpected CHAR. [1:476: <]
2025-05-21 08:22:04,365 - ERROR - errorhandler.py:105 - SelectorList: Invalid Selector: <br>            th
2025-05-21 08:22:04,370 - ERROR - errorhandler.py:105 - Selector: Unexpected CHAR. [1:558: <]
2025-05-21 08:22:04,370 - ERROR - errorhandler.py:105 - SelectorList: Invalid Selector: <br>            th 
2025-05-21 08:22:04,374 - ERROR - errorhandler.py:105 - CSSStyleRule: No start { of style declaration found: '<br>        ' [1:619: ]
2025-05-21 08:22:04,375 - ERROR - errorhandler.py:105 - Selector: Unexpected CHAR. [1:607: <]
2025-05-21 08:22:04,376 - ERROR - errorhandler.py:105 - Selector: Cannot end with combinator: <br>        
2025-05-21 08:22:04,377 - ERROR - errorhandler.py:105 - SelectorList: Invalid Selector: <br>        
2025-05-21 08:22:04,378 - ERROR - errorhandler.py:105 - CSSStyleRule: No style declaration or "}" found: '<br>        '
2025-05-21 08:22:06,912 - INFO - manejador_correo.py:144 - Correo enviado exitosamente usando Yagmail a: usuario.final@cliente.com, otro.usuario@cliente.com
2025-05-21 08:22:10,429 - INFO - sendTrujillo.py:236 - Correo para CDAMOSTRA 3231808 enviado con adjunto 'Trujillo_Muestra_3231808.xlsx'.
2025-05-21 08:22:14,035 - INFO - sendTrujillo.py:245 - --- Proceso completado para todos los pendientes ---
2025-05-21 08:22:14,213 - INFO - sendTrujillo.py:256 - ********** FIN DEL PROCESO DE ENVÍO DE INFORMES **********
2025-05-21 08:27:03,117 - INFO - sendTrujillo.py:98 - Sistema de Logging configurado.
2025-05-21 08:27:03,120 - INFO - sendTrujillo.py:153 - ********** INICIO DEL PROCESO DE ENVÍO DE INFORMES **********
2025-05-21 08:27:05,797 - INFO - sendTrujillo.py:173 - Se encontraron 1 CDAMOSTRAS pendientes para procesar.
2025-05-21 08:27:05,799 - INFO - sendTrujillo.py:106 - --- Iniciando procesamiento para CDAMOSTRA: 3231808 ---
2025-05-21 08:27:06,466 - INFO - sendTrujillo.py:118 - Resultados obtenidos para 3231808: 2 filas.
2025-05-21 08:27:06,927 - INFO - sendTrujillo.py:130 - Encabezado obtenido para 3231808.
2025-05-21 08:27:09,385 - INFO - generador_excel.py:113 -  Excel para Trujillo 'informes_generados\Trujillo_Muestra_3231808.xlsx' creado exitosamente para muestra PACK 2 SUPER EXPRESS.
2025-05-21 08:27:09,386 - INFO - sendTrujillo.py:213 - Excel 'informes_generados\Trujillo_Muestra_3231808.xlsx' generado exitosamente para CDAMOSTRA 3231808.
2025-05-21 08:27:09,394 - INFO - manejador_correo.py:109 - Archivo 'Trujillo_Muestra_3231808.xlsx' preparado para adjuntar.
2025-05-21 08:27:16,243 - INFO - manejador_correo.py:115 - Inicializando Yagmail para noreply.new@ceimic.com en smtp.office365.com:587
2025-05-21 08:27:30,876 - INFO - manejador_correo.py:133 - Intentando enviar correo a: ['usuario.final@cliente.com', 'otro.usuario@cliente.com'], Cc: ['supervisor@ceimic.com'], Bcc: ['auditoria.interna@ceimic.com']
2025-05-21 08:28:06,083 - INFO - sendTrujillo.py:98 - Sistema de Logging configurado.
2025-05-21 08:28:06,085 - INFO - sendTrujillo.py:153 - ********** INICIO DEL PROCESO DE ENVÍO DE INFORMES **********
2025-05-21 08:28:08,155 - INFO - sendTrujillo.py:173 - Se encontraron 1 CDAMOSTRAS pendientes para procesar.
2025-05-21 08:28:08,156 - INFO - sendTrujillo.py:106 - --- Iniciando procesamiento para CDAMOSTRA: 3231808 ---
2025-05-21 08:28:08,825 - INFO - sendTrujillo.py:118 - Resultados obtenidos para 3231808: 2 filas.
2025-05-21 08:28:09,280 - INFO - sendTrujillo.py:130 - Encabezado obtenido para 3231808.
2025-05-21 08:28:10,024 - INFO - generador_excel.py:113 -  Excel para Trujillo 'informes_generados\Trujillo_Muestra_3231808.xlsx' creado exitosamente para muestra PACK 2 SUPER EXPRESS.
2025-05-21 08:28:10,026 - INFO - sendTrujillo.py:213 - Excel 'informes_generados\Trujillo_Muestra_3231808.xlsx' generado exitosamente para CDAMOSTRA 3231808.
2025-05-21 08:28:10,028 - INFO - manejador_correo.py:109 - Archivo 'Trujillo_Muestra_3231808.xlsx' preparado para adjuntar.
2025-05-21 08:28:11,870 - INFO - manejador_correo.py:115 - Inicializando Yagmail para noreply.new@ceimic.com en smtp.office365.com:587
2025-05-21 08:28:13,648 - INFO - manejador_correo.py:133 - Intentando enviar correo a: ['usuario.final@cliente.com', 'otro.usuario@cliente.com'], Cc: ['supervisor@ceimic.com'], Bcc: ['auditoria.interna@ceimic.com']
2025-05-21 08:31:59,688 - INFO - sendTrujillo.py:98 - Sistema de Logging configurado.
2025-05-21 08:31:59,690 - INFO - sendTrujillo.py:153 - ********** INICIO DEL PROCESO DE ENVÍO DE INFORMES **********
2025-05-21 08:32:01,785 - INFO - sendTrujillo.py:171 - Se encontraron 1 CDAMOSTRAS pendientes para procesar.
2025-05-21 08:32:01,787 - INFO - sendTrujillo.py:106 - --- Iniciando procesamiento para CDAMOSTRA: 3231808 ---
2025-05-21 08:32:03,181 - INFO - sendTrujillo.py:118 - Resultados obtenidos para 3231808: 2 filas.
2025-05-21 08:32:03,676 - INFO - sendTrujillo.py:130 - Encabezado obtenido para 3231808.
2025-05-21 08:32:05,082 - INFO - generador_excel.py:113 -  Excel para Trujillo 'informes_generados\Trujillo_Muestra_3231808.xlsx' creado exitosamente para muestra PACK 2 SUPER EXPRESS.
2025-05-21 08:32:05,084 - INFO - sendTrujillo.py:211 - Excel 'informes_generados\Trujillo_Muestra_3231808.xlsx' generado exitosamente para CDAMOSTRA 3231808.
2025-05-21 08:32:05,087 - INFO - manejador_correo.py:109 - Archivo 'Trujillo_Muestra_3231808.xlsx' preparado para adjuntar.
2025-05-21 08:32:06,499 - INFO - manejador_correo.py:115 - Inicializando Yagmail para noreply.new@ceimic.com en smtp.office365.com:587
2025-05-21 08:32:12,650 - INFO - manejador_correo.py:133 - Intentando enviar correo a: ['Eder.ortega@ceimic.com', 'joel.zarate@ceimic.com'], Cc: ['herrick.davis@ceimic.com'], Bcc: ['herrick.davis@ceimic.com']
2025-05-21 08:32:19,035 - ERROR - errorhandler.py:105 - Selector: Unexpected CHAR. [1:1: <]
2025-05-21 08:32:19,038 - ERROR - errorhandler.py:105 - SelectorList: Invalid Selector: <br>            body 
2025-05-21 08:32:19,116 - ERROR - errorhandler.py:105 - Selector: Unexpected CHAR. [1:75: <]
2025-05-21 08:32:19,118 - ERROR - errorhandler.py:105 - SelectorList: Invalid Selector: <br>            .container 
2025-05-21 08:32:19,637 - ERROR - errorhandler.py:105 - Selector: Unexpected CHAR. [1:178: <]
2025-05-21 08:32:19,638 - ERROR - errorhandler.py:105 - SelectorList: Invalid Selector: <br>            .header 
2025-05-21 08:32:19,733 - ERROR - errorhandler.py:105 - Selector: Unexpected CHAR. [1:267: <]
2025-05-21 08:32:19,734 - ERROR - errorhandler.py:105 - SelectorList: Invalid Selector: <br>            .content p 
2025-05-21 08:32:19,741 - ERROR - errorhandler.py:105 - Selector: Unexpected CHAR. [1:318: <]
2025-05-21 08:32:19,742 - ERROR - errorhandler.py:105 - SelectorList: Invalid Selector: <br>            .footer 
2025-05-21 08:32:19,813 - ERROR - errorhandler.py:105 - Selector: Unexpected CHAR. [1:394: <]
2025-05-21 08:32:19,814 - ERROR - errorhandler.py:105 - SelectorList: Invalid Selector: <br>            table 
2025-05-21 08:32:19,823 - ERROR - errorhandler.py:105 - Selector: Unexpected CHAR. [1:476: <]
2025-05-21 08:32:19,824 - ERROR - errorhandler.py:105 - SelectorList: Invalid Selector: <br>            th
2025-05-21 08:32:19,828 - ERROR - errorhandler.py:105 - Selector: Unexpected CHAR. [1:558: <]
2025-05-21 08:32:19,829 - ERROR - errorhandler.py:105 - SelectorList: Invalid Selector: <br>            th 
2025-05-21 08:32:19,832 - ERROR - errorhandler.py:105 - CSSStyleRule: No start { of style declaration found: '<br>        ' [1:619: ]
2025-05-21 08:32:19,834 - ERROR - errorhandler.py:105 - Selector: Unexpected CHAR. [1:607: <]
2025-05-21 08:32:19,835 - ERROR - errorhandler.py:105 - Selector: Cannot end with combinator: <br>        
2025-05-21 08:32:19,836 - ERROR - errorhandler.py:105 - SelectorList: Invalid Selector: <br>        
2025-05-21 08:32:19,836 - ERROR - errorhandler.py:105 - CSSStyleRule: No style declaration or "}" found: '<br>        '
2025-05-21 08:32:21,828 - INFO - manejador_correo.py:144 - Correo enviado exitosamente usando Yagmail a: Eder.ortega@ceimic.com, joel.zarate@ceimic.com
2025-05-21 08:32:25,696 - INFO - sendTrujillo.py:234 - Correo para CDAMOSTRA 3231808 enviado con adjunto 'Trujillo_Muestra_3231808.xlsx'.
2025-05-21 08:32:25,697 - INFO - sendTrujillo.py:243 - --- Proceso completado para todos los pendientes ---
2025-05-21 08:32:25,850 - INFO - sendTrujillo.py:254 - ********** FIN DEL PROCESO DE ENVÍO DE INFORMES **********
